<robot name = "robot">
    <link name="Torso">
        <inertial>
            <origin xyz="0 0 0.5" rpy="0 0 0"/>
            <mass value="1" />
            <inertia ixx="100" ixy="0" ixz="0" iyy="100" iyz="0" izz="100" />
        </inertial>
        <visual>
            <origin xyz="0 0 0.5" rpy="0 0 0"/>
            <geometry>
                <box size="0.8975600743097087 0.8932508297276442 0.17077659219122898" />
            </geometry>
            <material name="Cyan">
                <color rgba="0 1.0 1.0 1.0"/>
            </material>
        </visual>
        <collision>
            <origin xyz="0 0 0.5" rpy="0 0 0"/>
            <geometry>
                <box size="0.8975600743097087 0.8932508297276442 0.17077659219122898" />
            </geometry>
        </collision>
    </link>
    <joint name="Torso_Block0" type="revolute">
       <parent link="Torso"/>
       <child  link="Block0"/>
       <origin rpy="0 0 0" xyz="0 0 0.5" />
     <axis xyz="1 0 0"/>
       <limit effort="0.0" lower="-3.14159" upper="3.14159" velocity="0.0"/>
    </joint>
    <link name="Block0">
        <inertial>
            <origin xyz="0 0 0.0" rpy="0 0 0"/>
            <mass value="1" />
            <inertia ixx="100" ixy="0" ixz="0" iyy="100" iyz="0" izz="100" />
        </inertial>
        <visual>
            <origin xyz="0 0 0.0" rpy="0 0 0"/>
            <geometry>
                <box size="0.9443870964647999 0.2185945800835336 0.3589829335575604" />
            </geometry>
            <material name="Cyan">
                <color rgba="0 1.0 1.0 1.0"/>
            </material>
        </visual>
        <collision>
            <origin xyz="0 0 0.0" rpy="0 0 0"/>
            <geometry>
                <box size="0.9443870964647999 0.2185945800835336 0.3589829335575604" />
            </geometry>
        </collision>
    </link>
    <joint name="Block0_Block1" type="revolute">
       <parent link="Block0"/>
       <child  link="Block1"/>
       <origin rpy="0 0 0" xyz="0 0.0 0" />
     <axis xyz="1 0 0"/>
       <limit effort="0.0" lower="-3.14159" upper="3.14159" velocity="0.0"/>
    </joint>
    <link name="Block1">
        <inertial>
            <origin xyz="0 0.31715366595627875 0" rpy="0 0 0"/>
            <mass value="1" />
            <inertia ixx="100" ixy="0" ixz="0" iyy="100" iyz="0" izz="100" />
        </inertial>
        <visual>
            <origin xyz="0 0.31715366595627875 0" rpy="0 0 0"/>
            <geometry>
                <box size="0.7644985603397131 0.6343073319125575 0.8109758100493487" />
            </geometry>
            <material name="Cyan">
                <color rgba="0 1.0 1.0 1.0"/>
            </material>
        </visual>
        <collision>
            <origin xyz="0 0.31715366595627875 0" rpy="0 0 0"/>
            <geometry>
                <box size="0.7644985603397131 0.6343073319125575 0.8109758100493487" />
            </geometry>
        </collision>
    </link>
    <joint name="Block1_Block2" type="revolute">
       <parent link="Block1"/>
       <child  link="Block2"/>
       <origin rpy="0 0 0" xyz="0 0.0 0" />
     <axis xyz="1 0 0"/>
       <limit effort="0.0" lower="-3.14159" upper="3.14159" velocity="0.0"/>
    </joint>
    <link name="Block2">
        <inertial>
            <origin xyz="0 0.06026681250854387 0" rpy="0 0 0"/>
            <mass value="1" />
            <inertia ixx="100" ixy="0" ixz="0" iyy="100" iyz="0" izz="100" />
        </inertial>
        <visual>
            <origin xyz="0 0.06026681250854387 0" rpy="0 0 0"/>
            <geometry>
                <box size="0.5255787762048557 0.12053362501708774 0.5238504840173076" />
            </geometry>
            <material name="green">
                <color rgba="0 1.0 0 1,0"/>
            </material>
        </visual>
        <collision>
            <origin xyz="0 0.06026681250854387 0" rpy="0 0 0"/>
            <geometry>
                <box size="0.5255787762048557 0.12053362501708774 0.5238504840173076" />
            </geometry>
        </collision>
    </link>
</robot>