<robot name = "robot">
    <link name="Torso">
        <inertial>
            <origin xyz="0 0 0.5" rpy="0 0 0"/>
            <mass value="1" />
            <inertia ixx="100" ixy="0" ixz="0" iyy="100" iyz="0" izz="100" />
        </inertial>
        <visual>
            <origin xyz="0 0 0.5" rpy="0 0 0"/>
            <geometry>
                <box size="0.7064415333370083 0.6349178984076185 0.4361852952288675" />
            </geometry>
            <material name="green">
                <color rgba="0 1.0 0 1,0"/>
            </material>
        </visual>
        <collision>
            <origin xyz="0 0 0.5" rpy="0 0 0"/>
            <geometry>
                <box size="0.7064415333370083 0.6349178984076185 0.4361852952288675" />
            </geometry>
        </collision>
    </link>
    <joint name="Torso_Block0" type="revolute">
       <parent link="Torso"/>
       <child  link="Block0"/>
       <origin rpy="0 0 0" xyz="0.35322076666850416 0 0.5" />
     <axis xyz="1 0 0"/>
       <limit effort="0.0" lower="-3.14159" upper="3.14159" velocity="0.0"/>
    </joint>
    <link name="Block0">
        <inertial>
            <origin xyz="0.17968478064423066 0 0" rpy="0 0 0"/>
            <mass value="1" />
            <inertia ixx="100" ixy="0" ixz="0" iyy="100" iyz="0" izz="100" />
        </inertial>
        <visual>
            <origin xyz="0.17968478064423066 0 0" rpy="0 0 0"/>
            <geometry>
                <box size="0.3593695612884613 0.07897675253252755 0.7255903647976434" />
            </geometry>
            <material name="Cyan">
                <color rgba="0 1.0 1.0 1.0"/>
            </material>
        </visual>
        <collision>
            <origin xyz="0.17968478064423066 0 0" rpy="0 0 0"/>
            <geometry>
                <box size="0.3593695612884613 0.07897675253252755 0.7255903647976434" />
            </geometry>
        </collision>
    </link>
    <joint name="Block0_Block1" type="revolute">
       <parent link="Block0"/>
       <child  link="Block1"/>
       <origin rpy="0 0 0" xyz="0.17968478064423066 0.039488376266263774 0" />
     <axis xyz="1 0 0"/>
       <limit effort="0.0" lower="-3.14159" upper="3.14159" velocity="0.0"/>
    </joint>
    <link name="Block1">
        <inertial>
            <origin xyz="0 0.1387973690397215 0" rpy="0 0 0"/>
            <mass value="1" />
            <inertia ixx="100" ixy="0" ixz="0" iyy="100" iyz="0" izz="100" />
        </inertial>
        <visual>
            <origin xyz="0 0.1387973690397215 0" rpy="0 0 0"/>
            <geometry>
                <box size="0.3460631925009927 0.277594738079443 0.7254891466703048" />
            </geometry>
            <material name="Cyan">
                <color rgba="0 1.0 1.0 1.0"/>
            </material>
        </visual>
        <collision>
            <origin xyz="0 0.1387973690397215 0" rpy="0 0 0"/>
            <geometry>
                <box size="0.3460631925009927 0.277594738079443 0.7254891466703048" />
            </geometry>
        </collision>
    </link>
    <joint name="Block1_Block2" type="revolute">
       <parent link="Block1"/>
       <child  link="Block2"/>
       <origin rpy="0 0 0" xyz="0 0.1387973690397215 0" />
     <axis xyz="1 0 0"/>
       <limit effort="0.0" lower="-3.14159" upper="3.14159" velocity="0.0"/>
    </joint>
    <link name="Block2">
        <inertial>
            <origin xyz="0 0.7903192832409315 0" rpy="0 0 0"/>
            <mass value="1" />
            <inertia ixx="100" ixy="0" ixz="0" iyy="100" iyz="0" izz="100" />
        </inertial>
        <visual>
            <origin xyz="0 0.7903192832409315 0" rpy="0 0 0"/>
            <geometry>
                <box size="0.4561867395645859 1.580638566481863 0.7984699482394035" />
            </geometry>
            <material name="Cyan">
                <color rgba="0 1.0 1.0 1.0"/>
            </material>
        </visual>
        <collision>
            <origin xyz="0 0.7903192832409315 0" rpy="0 0 0"/>
            <geometry>
                <box size="0.4561867395645859 1.580638566481863 0.7984699482394035" />
            </geometry>
        </collision>
    </link>
    <joint name="Block2_Block3" type="revolute">
       <parent link="Block2"/>
       <child  link="Block3"/>
       <origin rpy="0 0 0" xyz="0.22809336978229294 0.7903192832409315 0" />
     <axis xyz="1 0 0"/>
       <limit effort="0.0" lower="-3.14159" upper="3.14159" velocity="0.0"/>
    </joint>
    <link name="Block3">
        <inertial>
            <origin xyz="0.18156707331586586 0 0" rpy="0 0 0"/>
            <mass value="1" />
            <inertia ixx="100" ixy="0" ixz="0" iyy="100" iyz="0" izz="100" />
        </inertial>
        <visual>
            <origin xyz="0.18156707331586586 0 0" rpy="0 0 0"/>
            <geometry>
                <box size="0.3631341466317317 0.05188567572749191 0.7532985114153139" />
            </geometry>
            <material name="Cyan">
                <color rgba="0 1.0 1.0 1.0"/>
            </material>
        </visual>
        <collision>
            <origin xyz="0.18156707331586586 0 0" rpy="0 0 0"/>
            <geometry>
                <box size="0.3631341466317317 0.05188567572749191 0.7532985114153139" />
            </geometry>
        </collision>
    </link>
</robot>