<robot name = "robot">
    <link name="Head">
        <inertial>
            <origin xyz="0 0 0.5" rpy="0 0 0"/>
            <mass value="1" />
            <inertia ixx="100" ixy="0" ixz="0" iyy="100" iyz="0" izz="100" />
        </inertial>
        <visual>
            <origin xyz="0 0 0.5" rpy="0 0 0"/>
            <geometry>
                <box size="0.3421407371440314 0.17220456429161485 0.6368261315858854" />
            </geometry>
            <material name="blue">
                <color rgba="0 1.0 1.0 1.0"/>
            </material>
        </visual>
        <collision>
            <origin xyz="0 0 0.5" rpy="0 0 0"/>
            <geometry>
                <box size="0.3421407371440314 0.17220456429161485 0.6368261315858854" />
            </geometry>
        </collision>
    </link>
    <joint name="j_0" type="revolute">
       <parent link="Head"/>
       <child  link="b0"/>
       <origin rpy="0 0 0" xyz="0 0.08610228214580742 0.5" />
     <axis xyz="1 0 0"/>
       <limit effort="0.0" lower="-3.14159" upper="3.14159" velocity="0.0"/>
    </joint>
    <link name="b0">
        <inertial>
            <origin xyz="0 0.47219398837882187 0" rpy="0 0 0"/>
            <mass value="1" />
            <inertia ixx="100" ixy="0" ixz="0" iyy="100" iyz="0" izz="100" />
        </inertial>
        <visual>
            <origin xyz="0 0.47219398837882187 0" rpy="0 0 0"/>
            <geometry>
                <box size="0.6621200821097591 0.9443879767576437 1.0050160900774379" />
            </geometry>
            <material name="green">
                <color rgba="0 1.0 0 1.0"/>
            </material>
        </visual>
        <collision>
            <origin xyz="0 0.47219398837882187 0" rpy="0 0 0"/>
            <geometry>
                <box size="0.6621200821097591 0.9443879767576437 1.0050160900774379" />
            </geometry>
        </collision>
    </link>
    <joint name="j_1" type="revolute">
       <parent link="b0"/>
       <child  link="b1"/>
       <origin rpy="0 0 0" xyz="0 0.08610228214580742 0" />
     <axis xyz="1 0 0"/>
       <limit effort="0.0" lower="-3.14159" upper="3.14159" velocity="0.0"/>
    </joint>
    <link name="b1">
        <inertial>
            <origin xyz="0 0.4271981845606253 0" rpy="0 0 0"/>
            <mass value="1" />
            <inertia ixx="100" ixy="0" ixz="0" iyy="100" iyz="0" izz="100" />
        </inertial>
        <visual>
            <origin xyz="0 0.4271981845606253 0" rpy="0 0 0"/>
            <geometry>
                <box size="0.09234140030676426 0.8543963691212506 0.5398709201067863" />
            </geometry>
            <material name="blue">
                <color rgba="0 1.0 1.0 1.0"/>
            </material>
        </visual>
        <collision>
            <origin xyz="0 0.4271981845606253 0" rpy="0 0 0"/>
            <geometry>
                <box size="0.09234140030676426 0.8543963691212506 0.5398709201067863" />
            </geometry>
        </collision>
    </link>
    <joint name="j_2" type="revolute">
       <parent link="b1"/>
       <child  link="b2"/>
       <origin rpy="0 0 0" xyz="0 0.08610228214580742 0" />
     <axis xyz="1 0 0"/>
       <limit effort="0.0" lower="-3.14159" upper="3.14159" velocity="0.0"/>
    </joint>
    <link name="b2">
        <inertial>
            <origin xyz="0 0.25808022190682256 0" rpy="0 0 0"/>
            <mass value="1" />
            <inertia ixx="100" ixy="0" ixz="0" iyy="100" iyz="0" izz="100" />
        </inertial>
        <visual>
            <origin xyz="0 0.25808022190682256 0" rpy="0 0 0"/>
            <geometry>
                <box size="1.0481023239233298 0.5161604438136451 0.6028913167039596" />
            </geometry>
            <material name="blue">
                <color rgba="0 1.0 1.0 1.0"/>
            </material>
        </visual>
        <collision>
            <origin xyz="0 0.25808022190682256 0" rpy="0 0 0"/>
            <geometry>
                <box size="1.0481023239233298 0.5161604438136451 0.6028913167039596" />
            </geometry>
        </collision>
    </link>
    <joint name="j_3" type="revolute">
       <parent link="b2"/>
       <child  link="b3"/>
       <origin rpy="0 0 0" xyz="0 0.08610228214580742 0" />
     <axis xyz="1 0 0"/>
       <limit effort="0.0" lower="-3.14159" upper="3.14159" velocity="0.0"/>
    </joint>
    <link name="b3">
        <inertial>
            <origin xyz="0 0.15934263120710754 0" rpy="0 0 0"/>
            <mass value="1" />
            <inertia ixx="100" ixy="0" ixz="0" iyy="100" iyz="0" izz="100" />
        </inertial>
        <visual>
            <origin xyz="0 0.15934263120710754 0" rpy="0 0 0"/>
            <geometry>
                <box size="0.7695193699538131 0.3186852624142151 0.21376669994244496" />
            </geometry>
            <material name="green">
                <color rgba="0 1.0 0 1.0"/>
            </material>
        </visual>
        <collision>
            <origin xyz="0 0.15934263120710754 0" rpy="0 0 0"/>
            <geometry>
                <box size="0.7695193699538131 0.3186852624142151 0.21376669994244496" />
            </geometry>
        </collision>
    </link>
    <joint name="j_4" type="revolute">
       <parent link="b3"/>
       <child  link="b4"/>
       <origin rpy="0 0 0" xyz="0 0.08610228214580742 0" />
     <axis xyz="1 0 0"/>
       <limit effort="0.0" lower="-3.14159" upper="3.14159" velocity="0.0"/>
    </joint>
    <link name="b4">
        <inertial>
            <origin xyz="0 0.10154094220167234 0" rpy="0 0 0"/>
            <mass value="1" />
            <inertia ixx="100" ixy="0" ixz="0" iyy="100" iyz="0" izz="100" />
        </inertial>
        <visual>
            <origin xyz="0 0.10154094220167234 0" rpy="0 0 0"/>
            <geometry>
                <box size="0.18222479552472154 0.20308188440334468 0.4302999136272612" />
            </geometry>
            <material name="blue">
                <color rgba="0 1.0 1.0 1.0"/>
            </material>
        </visual>
        <collision>
            <origin xyz="0 0.10154094220167234 0" rpy="0 0 0"/>
            <geometry>
                <box size="0.18222479552472154 0.20308188440334468 0.4302999136272612" />
            </geometry>
        </collision>
    </link>
</robot>